Workbook

Sheet Datos Generales
A1: Commodity | B1: Cuenta Contable | C1: Aprobador
A2: 50302002 | B2: 3305012006 | C2: javiermancilla@natura.net
C3: antonellabontempi@natura.net
C4: guillermo.badilla@natura.net
C5: flaviamoura@natura.net

Sheet Hoja 6
A1: SAFRA | B1: CECO | C1: SAP | D1: TIENDA | E1: CECO | F1: SUPERVISOR | G1: ZONA | H1: REGIÓN | I1: COMUNA | J1: CADENA MALL | K1: STATUS | L1: GRUPO | M1: PEDIDO | N1: TIPO | O1: CHRONOS | P1: EKOS | Q1: ERVA DOCE | R1: ESSENCIAL | S1: FOTOEQUILIBRIO | T1: HOMEM | U1: HUMOR | V1: ILÍA | W1: KAIAK | X1: LUMINA | Y1: LUNA | Z1: UNA | AA1: TODODIA | AB1: SEVE | AC1: KRISKA | AD1: FACES | AE1: MMBB | AF1: NATURÉ | AG1: DIRECCIÓN | AH1: HORARIO MALL | AI1: EMAIL TIENDA | AJ1: JEFE | AK1: 2do | AL1: TELEFONO TIENDA | AM1: TELEFONO SUPERVISOR | AN1: HORARIO MALL | AO1: ID OMNI | AP1: Codigo Tienda | AQ1: MALLA OMNI | AR1: RETIRO EN TIENDA | AS1: SUPER EXPRESS | AT1: ABBIAMO
A2: 4 | B2: 41001095 | C2: 4147 | D2: PLAZA SUR | E2: =VLOOKUP(B2,'Maestros de Tiendas'!J:J,1,0) -> #REF! | F2: MARIA ANGELICA MEDINA | G2: ZONA SUR | H2: METROPOLITANA | I2: SAN BERNARDO | J2: MALLPLAZA | K2: APERTURADA | L2: 2 | M2: QUINCENAL | N2: ATHENA | O2: X | P2: X | Q2: X | R2: X | S2: X | T2: X | U2: X | V2: X | W2: X | X2: X | Y2: X | Z2: X | AA2: X | AB2: X | AC2: X | AD2: X | AE2: X | AF2: X | AG2: AV. PDTE. JORGE ALESSANDRI RODRÍGUEZ 20040, LOCAL 1054-1056, SAN BERNARDO, REGIÓN METROPOLITANA | AH2: LUNES A VIERNES DE 09:00 A 12:00PM | AI2: mallplazasur@natura.net | AJ2: Beatriz Falcao | AK2: NO TIENE | AL2: 9 26255648 | AM2: 9 74895268 | AO2: 336 | AP2: 9033 | AQ2: X | AR2: ACTIVA | AS2: INACTIVA | AT2: X
A3: 4 | B3: 41001098 | C3: 4148 | D3: PLAZA COPIAPO | E3: =VLOOKUP(B3,'Maestros de Tiendas'!J:J,1,0) -> #REF! | F3: LUIS GUZMAN | G3: ZONA NORTE | H3: ATACAMA | I3: COPIAPO | J3: MALLPLAZA | K3: APERTURADA | L3: 1 | M3: QUINCENAL | N3: ATHENA | O3: X | P3: X | Q3: X | R3: X | S3: X | T3: X | U3: X | V3: X | W3: X | X3: X | Y3: X | Z3: X | AA3: X | AB3: X | AC3: X | AD3: X | AE3: X | AF3: X | AG3: MAIPÚ 109, LOCAL 2188-2192, COPIAPÓ, ATACAMA | AH3: LUNES A VIERNES DE 09:00 A 12:00PM | AI3: Mallplazacopiapo@natura.net | AJ3: Camila Gallegos | AK3: NO TIENE | AL3: 9 26255541 | AM3: 9 31999099 | AO3: 335 | AP3: 9032 | AQ3: X | AR3: ACTIVA | AS3: INACTIVA | AT3: X
A4: 4 | B4: 41003113 | C4: 4149 | D4: ARAUCO QUILICURA | E4: =VLOOKUP(B4,'Maestros de Tiendas'!J:J,1,0) -> #REF! | F4: SEBASTIAN VEGAS | G4: ZONA CENTRO | H4: METROPOLITANA | I4: QUILICURA | J4: PARQUE ARAUCO | K4: APERTURADA | L4: 2 | M4: QUINCENAL | N4: ATHENA | O4: X | P4: X | Q4: X | R4: X | S4: X | T4: X | U4: X | V4: X | W4: X | X4: X | Y4: X | Z4: X | AA4: X | AB4: X | AC4: X | AD4: X | AE4: X | AF4: X | AG4: AV. BERNARDO O'HIGGINS 581, LOCAL S40, 8700000 QUILICURA, REGIÓN METROPOLITANA | AH4: LUNES A SABADO DE 08:00 A 11:00 HRS | AI4: Araucoquilicura@natura.net | AJ4: Silvana Flores | AK4: NO TIENE | AL4: 9 63096332 | AM4: 9 33796935 | AO4: 338 | AP4: 36 | AQ4: X | AR4: ACTIVA | AS4: INACTIVA | AT4: X
A5: 4 | B5: 41003116 | C5: 4150 | D5: GRAN AVENIDA | E5: =VLOOKUP(B5,'Maestros de Tiendas'!J:J,1,0) -> #REF! | F5: SEBASTIAN VEGAS | G5: ZONA CENTRO | H5: METROPOLITANA | I5: SAN MIGUEL | J5: ESPACIO URBANO | K5: APERTURADA | L5: 2 | M5: QUINCENAL | N5: ATHENA | O5: X | P5: X | Q5: X | R5: X | S5: X | T5: X | U5: X | V5: X | W5: X | X5: X | Y5: X | Z5: X | AA5: X | AB5: X | AC5: X | AD5: X | AE5: X | AF5: X | AG5: GRAN AV. JOSÉ MIGUEL CARRERA 6150, LOCAL 1144, 8930520 SAN MIGUEL, REGIÓN METROPOLITANA | AH5: LUNES A VIERNES DE 08:00 A 12:00 HRS | AI5: Granavenida@natura.net | AJ5: Astrid Contreras | AK5: Patricia Ugas | AL5: 9 26255560 | AM5: 9 33796935 | AO5: 337 | AP5: 34 | AQ5: X | AR5: ACTIVA | AS5: INACTIVA | AT5: X
A6: 4 | B6: 41001152 | C6: 4151 | D6: PASEO QUILIN | E6: =VLOOKUP(B6,'Maestros de Tiendas'!J:J,1,0) -> #REF! | F6: SEBASTIAN VEGAS | G6: ZONA CENTRO | H6: METROPOLITANA | I6: PEÑALOLEN | J6: PASEO QUILIN | K6: APERTURADA | L6: 2 | M6: QUINCENAL | N6: ATHENA | O6: X | P6: X | Q6: X | R6: X | S6: X | T6: X | U6: X | V6: X | W6: X | X6: X | Y6: X | Z6: X | AA6: X | AB6: X | AC6: X | AD6: X | AE6: X | AF6: X | AG6: MAR TIRRENO Nº 3.349, LOCAL 2024-2026, PEÑALOLÉN, REGIÓN METROPOLITANA | AH6: LUNES A VIERNES DE 07:00 A 12:00 HRS. | AI6: Paseoquilin@natura.net | AJ6: Jazmin duran saez | AK6: NO TIENE | AM6: 9 33796935 | AO6: 340 | AP6: 9038 | AQ6: X | AR6: ACTIVA | AS6: INACTIVA | AT6: X
A7: 4 | B7: 41003117 | C7: 4152 | D7: CASTRO | E7: =VLOOKUP(B7,'Maestros de Tiendas'!J:J,1,0) -> #REF! | F7: MARIA ANGELICA MEDINA | G7: ZONA SUR | H7: LOS LAGOS | I7: CASTRO | J7: PASMAR | K7: APERTURADA | L7: 1 | M7: QUINCENAL | N7: ATHENA | O7: X | P7: X | Q7: X | R7: X | S7: X | T7: X | U7: X | V7: X | W7: X | X7: X | Y7: X | Z7: X | AA7: X | AB7: X | AC7: X | AD7: X | AE7: X | AF7: X | AG7: IGNACIO SERRANO 574, LOCAL 305 A, CASTRO, REGIÓN LOS LAGOS | AI7: Paseochiloe@natura.net | AJ7: Gabriela Torres | AK7: Damaris Muñoz | AL7: 9 56807241 | AM7: 9 74895268 | AO7: 339 | AP7: 9037 | AQ7: X | AR7: ACTIVA | AS7: INACTIVA | AT7: X
A8: 4 | B8: 41001156 | C8: 4154 | D8: PUERTO MONTT | E8: =VLOOKUP(B8,'Maestros de Tiendas'!J:J,1,0) -> #REF! | F8: MARIA ANGELICA MEDINA | G8: ZONA SUR | H8: LOS LAGOS | I8: PUERTO MONTT | J8: ZONA AUSTRAL | K8: APERTURADA | L8: 2 | M8: QUINCENAL | N8: ATHENA | O8: X | P8: X | Q8: X | R8: X | S8: X | T8: X | U8: X | V8: X | W8: X | X8: X | Y8: X | Z8: X | AA8: X | AB8: X | AC8: X | AD8: X | AE8: X | AF8: X | AG8: JUAN SOLER MANFREDINI N°131, LOCAL 105, PUERTO MONTT, REGION LOS LAGOS | AH8: LUNES A SABADO DE 8:30 A 10:00HRS | AI8: Mallpaseocostanera@natura.net | AJ8: Paola Leal | AK8: NO TIENE | AL8: 9 46527653 | AM8: 9 74895268 | AO8: 373 | AP8: 9041 | AQ8: X | AR8: ACTIVA | AS8: INACTIVA | AT8: X
A9: 4 | B9: 41003118 | C9: 4153 | D9: PUNTA ARENAS | E9: =VLOOKUP(B9,'Maestros de Tiendas'!J:J,1,0) -> #REF! | F9: MARIA ANGELICA MEDINA | G9: ZONA SUR | H9: MAGALLANES | I9: PUNTA ARENAS | J9: PASMAR | K9: APERTURADA | L9: 2 | M9: QUINCENAL | N9: ATHENA | O9: X | P9: X | Q9: X | R9: X | S9: X | T9: X | U9: X | V9: X | W9: X | X9: X | Y9: X | Z9: X | AA9: X | AB9: X | AC9: X | AD9: X | AE9: X | AF9: X | AG9: AV. BULNES KM. 3,5 NORTE, LOCAL 403, PUNTA ARENAS, REGIÓN MAGALLANES | AH9: LUNES A VIERNES 08:30 A 13:00 HRS. | AI9: Puntaarenas@natura.net | AJ9: Jaqueline Perez | AK9: NO TIENE | AL9: 9 26255591 | AM9: 9 74895268 | AO9: 341 | AP9: 9039 | AQ9: X | AR9: ACTIVA | AS9: INACTIVA | AT9: X
A10: 4 | B10: 41001161 | C10: 4155 | D10: MALL PASEO ROSS | E10: =VLOOKUP(B10,'Maestros de Tiendas'!J:J,1,0) -> #REF! | F10: LUIS GUZMAN | G10: ZONA NORTE | H10: VALPARAISO | I10: VALPARAISO | J10: PASEO ROSS | K10: APERTURADA | L10: 2 | M10: QUINCENAL | N10: ATHENA | O10: X | P10: X | Q10: X | R10: X | S10: X | T10: X | U10: X | V10: X | W10: X | X10: X | Y10: X | Z10: X | AA10: X | AB10: X | AC10: X | AD10: X | AE10: X | AF10: X | AG10: AVENIDA ARGENTINA 540, LOCAL 319-321, VALPARAISO | AH10: LUNES A VIERNES DE 09:30 12:30 PM | AI10: mallpaseoross@natura.net | AJ10: Francisca Munzón | AK10: NO TIENE | AL10: 9 44257647 | AM10: 9 31999099 | AO10: 372 | AP10: 9040 | AQ10: X | AR10: ACTIVA | AS10: INACTIVA | AT10: X
A11: 4 | B11: 41001164 | C11: 4156 | D11: COQUIMBO | E11: =VLOOKUP(B11,'Maestros de Tiendas'!J:J,1,0) -> #REF! | F11: LUIS GUZMAN | G11: ZONA NORTE | H11: COQUIMBO | I11: COQUIMBO | J11: GRUPO VIVO | K11: APERTURADA | L11: 1 | M11: QUINCENAL | N11: ATHENA | O11: X | P11: X | Q11: X | R11: X | S11: X | T11: X | U11: X | V11: X | W11: X | X11: X | Y11: X | Z11: X | AA11: X | AB11: X | AC11: X | AD11: X | AE11: X | AF11: X | AG11: AVENIDA VARELA 1524, LOCAL 2128, COQUIMBO | AH11: LUNES A DOMINGO DE 08:00 A 09:45 HRS. | AI11: Mallvivocoquimbo@natura.net | AJ11: Cristina Esquivel | AK11: NO TIENE | AL11: 9 26255563 | AM11: 9 31999099 | AO11: 374 | AP11: 9042 | AQ11: X | AR11: ACTIVA | AS11: INACTIVA | AT11: X
A12: 5 | B12: 41001176 | C12: 4157 | D12: OPEN OVALLE | E12: =VLOOKUP(B12,'Maestros de Tiendas'!J:J,1,0) -> #REF! | F12: LUIS GUZMAN | G12: ZONA NORTE | H12: COQUIMBO | I12: OVALLE | J12: OPEN PLAZA | K12: APERTURADA | L12: 1 | M12: QUINCENAL | N12: ATHENA | AG12: PROLONGACIÓN BENAVENTE N° 1075, LOCAL 1180, COMUNA Y CIUDAD DE OVALLE, REGIÓN DE COQUIMBO. | AI12: OP.Ovalle@natura.net | AJ12: Camila Donoso | AM12: 9 31999099 | AO12: 417 | AP12: 9047 | AQ12: X | AR12: INACTIVA | AS12: INACTIVA
A13: 5 | B13: 41001177 | C13: 4158 | D13: EU PUENTE ALTO | E13: =VLOOKUP(B13,'Maestros de Tiendas'!J:J,1,0) -> #REF! | F13: SEBASTIAN VEGAS | G13: ZONA CENTRO | H13: METROPOLITANA | I13: PUENTE ALTO | J13: ESPACIO URBANO | K13: APERTURADA | L13: 1 | M13: QUINCENAL | N13: ATHENA | AG13: AVENIDA CONCHA Y TORO 1149, PUENTE ALTO, CHILE | AI13: eu.puentealto@natura.net | AJ13: Patricia López | AM13: 9 33796935 | AO13: 416 | AP13: 9046 | AQ13: X | AR13: INACTIVA | AS13: INACTIVA
A14: 5 | B14: 41001181 | C14: 4159 | D14: MELIPILLA | E14: =VLOOKUP(B14,'Maestros de Tiendas'!J:J,1,0) -> #REF! | F14: SEBASTIAN VEGAS | G14: ZONA CENTRO | H14: METROPOLITANA | I14: MELIPILLA | J14: ESPACIO URBANO | K14: APERTURADA | M14: QUINCENAL | N14: ATHENA | AG14: SERRANO 395, LOCAL 215, MELIPILLA | AI14: e.u.melipilla@natura.net | AJ14: Carolina Acevedo | AM14: 9 33796935
A15: 5 | B15: 41001163 | C15: 4160 | D15: AEROPUERTO | E15: =VLOOKUP(B15,'Maestros de Tiendas'!J:J,1,0) -> #REF! | F15: SEBASTIAN VEGAS | G15: ZONA CENTRO | H15: METROPOLITANA | I15: PUDAHUEL | J15: AEROPUERTO | K15: CONSTRUCCIÓN | M15: QUINCENAL | N15: ATHENA | AG15: ARMANDO CORTINEZ NORTE N° 11501, LOTEO AEROPUERTO C.A.M.B., LOCAL 800-5-1-B17C, COMUNA DE PUDAHUEL | AI15: aeropuerto@natura.net | AM15: 9 33796935 | AO15: 375 | AP15: 9043 | AQ15: X | AR15: INACTIVA | AS15: INACTIVA
A16: 1 | B16: 41003043 | C16: 4161 | D16: DOMINICOS | E16: =VLOOKUP(B16,'Maestros de Tiendas'!J:J,1,0) -> #REF! | F16: SEBASTIAN VEGAS | G16: ZONA CENTRO | H16: METROPOLITANA | I16: LAS CONDES | J16: MALLPLAZA | K16: APERTURADA | L16: 1 | M16: QUINCENAL | N16: AURORA | O16: X | P16: X | Q16: X | R16: X | S16: X | T16: X | U16: X | V16: X | W16: X | X16: X | Y16: X | Z16: X | AA16: X | AB16: X | AC16: X | AE16: X | AG16: AV. PADRE HURTADO SUR 875, LOCAL A-2029/A-2033, LAS CONDES | AH16: LUNES A SÁBADO DE 08:00 A 12:00HRS Y DESDE LAS 20:00 HRS EN LA NOCHE | AI16: Dominicoscl@natura.net | AJ16: Mary Paz Oyarzun | AK16: Azul Calquin | AL16: 9 32479793 | AM16: 9 33796935 | AO16: 115 | AP16: 901 | AQ16: X | AR16: ACTIVA | AS16: INACTIVA | AT16: X
A17: 1 | B17: 41003042 | C17: 4162 | D17: COSTANERA | E17: =VLOOKUP(B17,'Maestros de Tiendas'!J:J,1,0) -> #REF! | F17: SEBASTIAN VEGAS | G17: ZONA CENTRO | H17: METROPOLITANA | I17: PROVIDENCIA | J17: CENCOSUD | K17: APERTURADA | L17: 0 | M17: SEMANAL | N17: AURORA | O17: X | P17: X | Q17: X | R17: X | S17: X | T17: X | U17: X | V17: X | W17: X | X17: X | Y17: X | Z17: X | AA17: X | AB17: X | AC17: X | AE17: X | AG17: AV. ANDRÉS BELLO 2425, LOCAL 2188, PROVIDENCIA | AH17: LUNES A VIERNES DE 09:00 A 12:00PM | AI17: Costaneracl@natura.net | AJ17: Vivianny Perez | AK17: Geraldine Naveda | AL17: 9 32479819 | AM17: 9 33796935 | AO17: 106 | AP17: 91001 | AQ17: X | AR17: ACTIVA | AS17: INACTIVA | AT17: X
A18: 1 | B18: 41003008 | C18: 4163 | D18: EGAÑA | E18: =VLOOKUP(B18,'Maestros de Tiendas'!J:J,1,0) -> #REF! | F18: LUIS GUZMAN | G18: ZONA NORTE | H18: METROPOLITANA | I18: LA REINA | J18: MALLPLAZA | K18: APERTURADA | L18: 1 | M18: QUINCENAL | N18: AURORA | O18: X | P18: X | Q18: X | R18: X | S18: X | T18: X | U18: X | V18: X | W18: X | X18: X | Y18: X | Z18: X | AA18: X | AB18: X | AC18: X | AE18: X | AG18: AV. LARRAIN 5862, LOCAL B-1077, LA REINA | AH18: LUNES A VIERNES DE 09:00 A 12:00PM | AI18: Plazaeganacl@natura.net | AJ18: Ely Blanco | AK18: Aida Medina Campos | AL18: 9 32479778 | AM18: 9 31999099 | AO18: 98 | AP18: 9100002 | AQ18: X | AR18: ACTIVA | AS18: INACTIVA | AT18: X
A19: 1 | B19: 41003009 | C19: 4164 | D19: NORTE | E19: =VLOOKUP(B19,'Maestros de Tiendas'!J:J,1,0) -> #REF! | F19: MARIA ANGELICA MEDINA | G19: ZONA SUR | H19: METROPOLITANA | I19: HUECHURABA | J19: MALLPLAZA | K19: APERTURADA | L19: 2 | M19: QUINCENAL | N19: ATHENA | O19: X | P19: X | Q19: X | R19: X | S19: X | T19: X | U19: X | V19: X | W19: X | X19: X | Y19: X | Z19: X | AA19: X | AB19: X | AC19: X | AD19: X | AE19: X | AF19: X | AG19: AV. AMÉRICO VESPUCIO 1737, LOCAL A-1128, HUECHURABA | AH19: LUNES A VIERNES DE 8:00 A 14:00 HRS | AI19: Plazanortecl@natura.net | AJ19: Matias Sanhueza | AK19: NO TIENE | AL19: 9 32479790 | AM19: 9 74895268 | AO19: 103 | AP19: 9123 | AQ19: X | AR19: ACTIVA | AS19: INACTIVA | AT19: X
A20: 2 | B20: 41003010 | C20: 4165 | D20: VESPUCIO | E20: =VLOOKUP(B20,'Maestros de Tiendas'!J:J,1,0) -> #REF! | F20: SEBASTIAN VEGAS | G20: ZONA CENTRO | H20: METROPOLITANA | I20: LA FLORIDA | J20: MALLPLAZA | K20: APERTURADA | L20: 0 | M20: SEMANAL | N20: ATHENA | O20: X | P20: X | Q20: X | R20: X | S20: X | T20: X | U20: X | V20: X | W20: X | X20: X | Y20: X | Z20: X | AA20: X | AB20: X | AC20: X | AD20: X | AE20: X | AF20: X | AG20: AV. VICUÑA MACKENNA 7110, LOCAL 117, LA FLORIDA | AH20: LUNES A SABADO 08:00 11:00 AM | AI20: Plazavespucio@natura.net | AJ20: Eduardo Meneses | AK20: Macarena | AL20: 9 87808312 | AM20: 9 33796935 | AO20: 105 | AP20: 912345 | AQ20: X | AR20: ACTIVA | AS20: INACTIVA | AT20: X
A21: 1 | B21: 41003011 | C21: 4166 | D21: PARQUE ARAUCO | E21: =VLOOKUP(B21,'Maestros de Tiendas'!J:J,1,0) -> #REF! | F21: LUIS GUZMAN | G21: ZONA NORTE | H21: METROPOLITANA | I21: LAS CONDES | J21: PARQUE ARAUCO | K21: APERTURADA | L21: 1 | M21: QUINCENAL | N21: AURORA | O21: X | P21: X | Q21: X | R21: X | S21: X | T21: X | U21: X | V21: X | W21: X | X21: X | Y21: X | Z21: X | AA21: X | AB21: X | AC21: X | AE21: X | AG21: AV PRESIDENTE KENNEDY 5413, LOCAL 83, LAS CONDES | AH21: LUNES A SABADO 8:00 A 10:00 AM | AI21: Parquearauco@natura.net | AJ21: Patricia Aguilera | AK21: NO TIENE | AL21: 9 74777895 | AM21: 9 31999099 | AO21: 160 | AP21: 9025 | AQ21: X | AR21: ACTIVA | AS21: INACTIVA | AT21: X
A22: 1 | B22: 41003016 | C22: 4168 | D22: ARAUCO MAIPU | E22: =VLOOKUP(B22,'Maestros de Tiendas'!J:J,1,0) -> #REF! | F22: LUIS GUZMAN | G22: ZONA NORTE | H22: METROPOLITANA | I22: MAIPU | J22: PARQUE ARAUCO | K22: APERTURADA | L22: 0 | M22: SEMANAL | N22: ATHENA | O22: X | P22: X | Q22: X | R22: X | S22: X | T22: X | U22: X | V22: X | W22: X | X22: X | Y22: X | Z22: X | AA22: X | AB22: X | AC22: X | AD22: X | AE22: X | AF22: X | AG22: AV. AMÉRICO VESPUCIO 399, LOCAL 645, MAIPÚ | AH22: LUNES A VIERNES DE 08:00 A 12:00HRS | AI22: Araucomaipu@natura.net | AJ22: norangela Higuera | AK22: Gianinna quiroz | AL22: 9 87808509 | AM22: 9 31999099 | AO22: 104 | AP22: 91234 | AQ22: X | AR22: ACTIVA | AS22: INACTIVA | AT22: X
A23: 2 | B23: 41003017 | C23: 4169 | D23: ALTO LAS CONDES | E23: =VLOOKUP(B23,'Maestros de Tiendas'!J:J,1,0) -> #REF! | F23: SEBASTIAN VEGAS | G23: ZONA CENTRO | H23: METROPOLITANA | I23: LAS CONDES | J23: CENCOSUD | K23: APERTURADA | L23: 1 | M23: QUINCENAL | N23: AURORA | O23: X | P23: X | Q23: X | R23: X | S23: X | T23: X | U23: X | V23: X | W23: X | X23: X | Y23: X | Z23: X | AA23: X | AB23: X | AC23: X | AE23: X | AG23: AV. PDTE. KENNEDY LATERAL 9001, LOCAL 2027, LAS CONDES | AH23: LUNES A VIERNES 21:00 HRS HASTA LAS 10:00 HRS | AI23: Altolascondes@natura.net | AJ23: Rosangelica Cegarra | AK23: Daniela De La Quintana | AL23: 9 87808529 | AM23: 9 33796935 | AO23: 107 | AP23: 91002 | AQ23: X | AR23: ACTIVA | AS23: INACTIVA | AT23: X
A24: 2 | B24: 41003019 | C24: 4170 | D24: MARINA | E24: =VLOOKUP(B24,'Maestros de Tiendas'!J:J,1,0) -> #REF! | F24: LUIS GUZMAN | G24: ZONA NORTE | H24: VALPARAISO | I24: VIÑA DE MAR | J24: GRUPO MARINA | K24: APERTURADA | L24: 2 | M24: QUINCENAL | N24: AURORA | O24: X | P24: X | Q24: X | R24: X | S24: X | T24: X | U24: X | V24: X | W24: X | X24: X | Y24: X | Z24: X | AA24: X | AB24: X | AC24: X | AE24: X | AG24: AVDA. LIBERTAD 1348, LOCAL 11, VIÑA DEL MAR | AH24: LUNES A SABADO DE 08:00 A 10:00 HRS O DE 20:30 A 21:00 | AI24: Marina@natura.net | AJ24: Pamela Carrasco | AK24: katerin ortiz | AL24: 9 87808722 | AM24: 9 31999099 | AO24: 162 | AP24: 9001 | AQ24: X | AR24: ACTIVA | AS24: INACTIVA | AT24: X
A25: 2 | B25: 41003021 | C25: 4171 | D25: OESTE | E25: =VLOOKUP(B25,'Maestros de Tiendas'!J:J,1,0) -> #REF! | F25: SEBASTIAN VEGAS | G25: ZONA CENTRO | H25: METROPOLITANA | I25: CERRILLOS | J25: MALLPLAZA | K25: APERTURADA | L25: 2 | M25: QUINCENAL | N25: ATHENA | O25: X | P25: X | Q25: X | R25: X | S25: X | T25: X | U25: X | V25: X | W25: X | X25: X | Y25: X | Z25: X | AA25: X | AB25: X | AC25: X | AD25: X | AE25: X | AF25: X | AG25: AVENIDA AMÉRICO VESPUCIO Nº 1501, LOCAL A-261/A-265, CERRILLOS | AH25: LUNES A SABADO 10:00 A 12:00 | AI25: Plazaoeste@natura.net | AJ25: Macarena Zamudio | AK25: Macarena Zamudio | AL25: 9 89656621 | AM25: 9 33796935 | AO25: 163 | AP25: 9002 | AQ25: X | AR25: ACTIVA | AS25: INACTIVA | AT25: X
A26: 3 | B26: 41003024 | C26: 4172 | D26: CONCEPCION CENTRO | E26: =VLOOKUP(B26,'Maestros de Tiendas'!J:J,1,0) -> #REF! | F26: MARIA ANGELICA MEDINA | G26: ZONA SUR | H26: BIO BIO | I26: CONCEPCIÓN | J26: GRUPO MARINA | K26: APERTURADA | L26: 2 | M26: QUINCENAL | N26: ATHENA | O26: X | P26: X | Q26: X | R26: X | S26: X | T26: X | U26: X | V26: X | W26: X | X26: X | Y26: X | Z26: X | AA26: X | AB26: X | AC26: X | AD26: X | AE26: X | AF26: X | AG26: BARROS ARANA 1068, LOCAL COMERCIAL Nº43 (24-02 USO INTERNO MALL), CONCEPCIÓN, BÍO BÍO | AH26: LUNES A SABADO DE 07:00 A 15:00 HRS | AI26: concecentro@natura.net | AJ26: Paola Osorio Jara | AK26: Fiorella Fajardo | AL26: 9 89656628 | AM26: 9 74895268 | AO26: 167 | AP26: 14 | AQ26: X | AR26: ACTIVA | AS26: INACTIVA | AT26: X
A27: 2 | B27: 41003022 | C27: 4173 | D27: TREBOL | E27: =VLOOKUP(B27,'Maestros de Tiendas'!J:J,1,0) -> #REF! | F27: MARIA ANGELICA MEDINA | G27: ZONA SUR | H27: BIO BIO | I27: TALCAHUANO | J27: MALLPLAZA | K27: APERTURADA | L27: 2 | M27: QUINCENAL | N27: AURORA | O27: X | P27: X | Q27: X | R27: X | S27: X | T27: X | U27: X | V27: X | W27: X | X27: X | Y27: X | Z27: X | AA27: X | AB27: X | AC27: X | AE27: X | AG27: AV. JORGE ALESSANDRI 3177, LOCAL A-130-132, TALCAHUANO | AH27: LUNES A SÁBADO DE 08:00 A 12:00HRS | AI27: Plazatrebol@natura.net | AJ27: Josefina Solis | AK27: Fernanda Vidal Soto | AL27: 9 89656629 | AM27: 9 74895268 | AO27: 164 | AP27: 9003 | AQ27: X | AR27: ACTIVA | AS27: INACTIVA | AT27: X
A28: 2 | B28: 41003020 | C28: 4175 | D28: FLORIDA | E28: =VLOOKUP(B28,'Maestros de Tiendas'!J:J,1,0) -> #REF! | F28: SEBASTIAN VEGAS | G28: ZONA CENTRO | H28: METROPOLITANA | I28: LA FLORIDA | J28: CENCOSUD | K28: APERTURADA | L28: 1 | M28: QUINCENAL | N28: ATHENA | O28: X | P28: X | Q28: X | R28: X | S28: X | T28: X | U28: X | V28: X | W28: X | X28: X | Y28: X | Z28: X | AA28: X | AB28: X | AC28: X | AD28: X | AE28: X | AF28: X | AG28: AV. VICUÑA MACKENNA OTE. 6100, LOCAL 3076, LA FLORIDA | AH28: LUNES A VIERNES DE 08:00 A 10:00 HRS Y 20:30 A 22:00 HRS | AI28: Florida.center@natura.net | AJ28: Nicolle Quintero | AK28: NO TIENE | AL28: 9 89656630 | AM28: 9 33796935 | AO28: 158 | AP28: 9011 | AQ28: X | AR28: ACTIVA | AS28: INACTIVA | AT28: X
A29: 3 | B29: 41003013 | C29: 4176 | D29: MUT | E29: =VLOOKUP(B29,'Maestros de Tiendas'!J:J,1,0) -> #REF! | F29: LUIS GUZMAN | G29: ZONA NORTE | H29: METROPOLITANA | I29: LAS CONDES | J29: TERRITORIA | K29: APERTURADA | L29: 2 | M29: QUINCENAL | N29: ATHENA | O29: X | P29: X | Q29: X | R29: X | S29: X | T29: X | U29: X | V29: X | W29: X | X29: X | Y29: X | Z29: X | AA29: X | AB29: X | AC29: X | AD29: X | AF29: X | AG29: AV. APOQUINDO 2750, LOCAL: F308-3044, LAS CONDES, 7550000, REGIÓN METROPOLITANA | AH29: LUNES A VIERNES DE 08:00 A 10:00 Y EN LA TARDE DESDE LAS 20:00 A 22:00 | AI29: Mercadourbano@natura.net | AK29: Ely Blanco | AL29: 9 31999120 | AM29: 9 31999099 | AO29: 165 | AP29: 3 | AQ29: X | AR29: ACTIVA | AS29: INACTIVA | AT29: X
A30: 2 | B30: 41003023 | C30: 4177 | D30: INDEPENDENCIA | E30: =VLOOKUP(B30,'Maestros de Tiendas'!J:J,1,0) -> #REF! | F30: MARIA ANGELICA MEDINA | G30: ZONA SUR | H30: METROPOLITANA | I30: INDEPENDENCIA | J30: GRUPO MARINA | K30: APERTURADA | L30: 2 | M30: QUINCENAL | N30: ATHENA | O30: X | P30: X | Q30: X | R30: X | S30: X | T30: X | U30: X | V30: X | W30: X | X30: X | Y30: X | Z30: X | AA30: X | AB30: X | AC30: X | AD30: X | AE30: X | AF30: X | AG30: AVENIDA INDEPENDENCIA N° 565, TM-140A, INDEPENDENCIA, RM | AH30: LUNES A SABADO 07:00 A 10:00 Y DE 20:00 A 21:00 | AI30: Barrioindependencia@natura.net | AJ30: Melissa Soto | AK30: Antonia Almendras | AL30: 9 89656626 | AM30: 9 74895268 | AO30: 159 | AP30: 9013 | AQ30: X | AR30: ACTIVA | AS30: INACTIVA | AT30: X
A31: 4 | B31: 41001096 | C31: 4178 | D31: PLAZA TOBALABA | E31: =VLOOKUP(B31,'Maestros de Tiendas'!J:J,1,0) -> #REF! | F31: SEBASTIAN VEGAS | G31: ZONA CENTRO | H31: METROPOLITANA | I31: PUENTE ALTO | J31: MALLPLAZA | K31: APERTURADA | L31: 1 | M31: QUINCENAL | N31: ATHENA | O31: X | P31: X | Q31: X | R31: X | S31: X | T31: X | U31: X | V31: X | W31: X | X31: X | Y31: X | Z31: X | AA31: X | AB31: X | AC31: X | AD31: X | AG31: AV. CAMILO HENRÍQUEZ 3692, LOCAL C-273/C-277, PUENTE ALTO, REGIÓN METROPOLITANA | AH31: LUNES A VIERNES DE 10:00 A 12:00 HRS | AI31: Plazatobalaba@natura.net | AJ31: Francia Farías | AK31: Camila Maulen | AM31: 9 33796935 | AO31: 330 | AP31: 27 | AQ31: X | AR31: ACTIVA | AS31: INACTIVA | AT31: X
A32: 4 | B32: 41001097 | C32: 4179 | D32: ARICA | E32: =VLOOKUP(B32,'Maestros de Tiendas'!J:J,1,0) -> #REF! | F32: LUIS GUZMAN | G32: ZONA NORTE | H32: ARICA Y PARINACOTA | I32: ARICA | J32: MALLPLAZA | K32: APERTURADA | L32: 2 | M32: QUINCENAL | N32: ATHENA | O32: X | P32: X | Q32: X | R32: X | S32: X | T32: X | U32: X | V32: X | W32: X | X32: X | Y32: X | Z32: X | AA32: X | AB32: X | AC32: X | AD32: X | AE32: X | AF32: X | AG32: AV. DIEGO PORTALES 640, LOCAL 1121-1125, ARICA, ARICA Y PARINACOTA | AH32: LUNES A VIERNES DE 9:30 A 12:00 HRS | AI32: Mallplazaarica@natura.net | AJ32: Poulette Vargas | AK32: Francesca Donoso | AL32: 9 26255668 | AM32: 9 31999099 | AO32: 333 | AP32: 30 | AQ32: X | AR32: ACTIVA | AS32: INACTIVA | AT32: X
A33: 3 | B33: 41003027 | C33: 4180 | D33: ANTOFAGASTA | E33: =VLOOKUP(B33,'Maestros de Tiendas'!J:J,1,0) -> #REF! | F33: LUIS GUZMAN | G33: ZONA NORTE | H33: ANTOFAGASTA | I33: ANTOFAGASTA | J33: MALLPLAZA | K33: APERTURADA | L33: 2 | M33: QUINCENAL | N33: ATHENA | O33: X | P33: X | Q33: X | R33: X | S33: X | T33: X | U33: X | V33: X | W33: X | X33: X | Y33: X | Z33: X | AA33: X | AB33: X | AC33: X | AD33: X | AE33: X | AF33: X | AG33: AV. BALMACEDA 2355, LOCAL 117, ANTOFAGASTA, REGION DE ANTOFAGASTA | AH33: LUNES A SABADO 10:00 A 12:00 HRS | AI33: MallPlazaantofagasta@natura.net | AJ33: Isabel Delgado | AK33: NO TIENE | AL33: 9 31999116 | AM33: 9 31999099 | AO33: 168 | AP33: 17 | AQ33: X | AR33: ACTIVA | AS33: INACTIVA | AT33: X
A34: 3 | B34: 41003026 | C34: 4181 | D34: CALAMA | E34: =VLOOKUP(B34,'Maestros de Tiendas'!J:J,1,0) -> #REF! | F34: LUIS GUZMAN | G34: ZONA NORTE | H34: ANTOFAGASTA | I34: CALAMA | J34: MALLPLAZA | K34: APERTURADA | L34: 1 | M34: QUINCENAL | N34: ATHENA | O34: X | P34: X | Q34: X | R34: X | S34: X | T34: X | U34: X | V34: X | W34: X | X34: X | Y34: X | Z34: X | AA34: X | AB34: X | AC34: X | AD34: X | AE34: X | AF34: X | AG34: AV. BALMACEDA 3242, LOCAL 153-157, CALAMA, REGION DE ANTOFAGASTA | AH34: LUNES A SABADO DE 10:00 A 12:00 | AI34: mallplazacalama@natura.net | AJ34: Claudia Pizarro | AK34: Sebastian Pasten | AL34: 9 31999101 | AM34: 9 31999099 | AO34: 169 | AP34: 18 | AQ34: X | AR34: ACTIVA | AS34: INACTIVA | AT34: X
A35: 3 | B35: 41003028 | C35: 4182 | D35: PUENTE | E35: =VLOOKUP(B35,'Maestros de Tiendas'!J:J,1,0) -> #REF! | F35: MARIA ANGELICA MEDINA | G35: ZONA SUR | H35: METROPOLITANA | I35: SANTIAGO CENTRO | J35: TRES ASOCIADOS | K35: APERTURADA | L35: 1 | M35: QUINCENAL | N35: ATHENA | O35: X | P35: X | Q35: X | R35: X | S35: X | T35: X | U35: X | V35: X | W35: X | X35: X | Y35: X | Z35: X | AA35: X | AB35: X | AC35: X | AD35: X | AF35: X | AG35: P.º PUENTE 689, LOCAL 145-147, SANTIAGO, REGION METROPOLITANA | AH35: LUNES A SABADO DE 8 A 15:00HRS | AI35: Mallvivocentro@natura.net | AJ35: Nataly Lopez | AK35: Raquel Aranda | AL35: 9 31999086 | AM35: 9 74895268 | AO35: 166 | AP35: 4 | AQ35: X | AR35: ACTIVA | AS35: INACTIVA | AT35: X
A36: 3 | B36: 41003029 | C36: 4183 | D36: ALAMEDA | E36: =VLOOKUP(B36,'Maestros de Tiendas'!J:J,1,0) -> #REF! | F36: MARIA ANGELICA MEDINA | G36: ZONA SUR | H36: METROPOLITANA | I36: ESTACIÓN CENTRAL | J36: MALLPLAZA | K36: APERTURADA | L36: 1 | M36: QUINCENAL | N36: ATHENA | O36: X | P36: X | Q36: X | R36: X | S36: X | T36: X | U36: X | V36: X | W36: X | X36: X | Y36: X | Z36: X | AA36: X | AB36: X | AC36: X | AD36: X | AE36: X | AF36: X | AG36: AV. DEL LIBERTADOR BERNARDO O'HIGGINS 3470, LOCAL A-126, ESTACION CENTRAL, RM | AH36: LUNES A SABADO DE 08:00 A 14:00 HRS | AI36: Alameda@natura.net | AJ36: Sandra Cabrera | AK36: Carolina Arellano | AL36: 9 31999115 | AM36: 9 74895268 | AO36: 170 | AP36: 19 | AQ36: X | AR36: ACTIVA | AS36: INACTIVA | AT36: X
A37: 3 | B37: 41001093 | C37: 4184 | D37: SUBCENTRO | E37: =VLOOKUP(B37,'Maestros de Tiendas'!J:J,1,0) -> #REF! | F37: LUIS GUZMAN | G37: ZONA NORTE | H37: METROPOLITANA | I37: LAS CONDES | J37: SUBCENTRO | K37: APERTURADA | L37: 1 | M37: QUINCENAL | N37: ATHENA | O37: X | P37: X | Q37: X | R37: X | S37: X | T37: X | U37: X | V37: X | W37: X | X37: X | Y37: X | Z37: X | AA37: X | AB37: X | AC37: X | AD37: X | AE37: X | AF37: X | AG37: AV. APOQUINDO 4411, LOCAL 154-156, LAS CONDES, REGIÓN METROPOLITANA | AH37: LUNES A SABADO 10.00 A 12.00 | AI37: Subcentro@natura.net | AJ37: Flavia Álvarez | AK37: Camila Escobar | AL37: 9 31999080 | AM37: 9 31999099 | AO37: 174 | AP37: 23 | AQ37: X | AR37: ACTIVA | AS37: INACTIVA | AT37: X
A38: 3 | B38: 41001101 | C38: 4185 | D38: VALDIVIA | E38: =VLOOKUP(B38,'Maestros de Tiendas'!J:J,1,0) -> #REF! | F38: MARIA ANGELICA MEDINA | G38: ZONA SUR | H38: LOS RIOS | I38: VALDIVIA | J38: PASMAR | K38: APERTURADA | L38: 1 | M38: QUINCENAL | N38: ATHENA | O38: X | P38: X | Q38: X | R38: X | S38: X | T38: X | U38: X | V38: X | W38: X | X38: X | Y38: X | Z38: X | AA38: X | AB38: X | AC38: X | AD38: X | AE38: X | AF38: X | AG38: AV. RAMÓN PICARTE 422, LOCAL L105A+105B, 5090000 VALDIVIA, LOS RÍOS | AH38: LUNES A VIERNES DE 08:00 A 09:30HRS. | AI38: Mallpaseovaldivia@natura.net | AJ38: Jennifer G | AK38: NO TIENE | AL38: 9 31999118 | AM38: 9 74895268 | AO38: 171 | AP38: 20 | AQ38: X | AR38: ACTIVA | AS38: INACTIVA | AT38: X
A39: 3 | B39: 41003030 | C39: 4186 | D39: OSORNO | E39: =VLOOKUP(B39,'Maestros de Tiendas'!J:J,1,0) -> #REF! | F39: MARIA ANGELICA MEDINA | G39: ZONA SUR | H39: LOS LAGOS | I39: OSORNO | J39: CENCOSUD | K39: APERTURADA | L39: 1 | M39: QUINCENAL | N39: ATHENA | O39: X | P39: X | Q39: X | R39: X | S39: X | T39: X | U39: X | V39: X | W39: X | X39: X | Y39: X | Z39: X | AA39: X | AB39: X | AC39: X | AD39: X | AE39: X | AF39: X | AG39: PLAZA YUNGAY, OSORNO 609, LOCAL 2067, OSORNO, LOS LAGOS | AH39: LUNES A VIERNES DE 8 A 10 AM | AI39: Portalosorno@natura.net | AJ39: Elizabeth Coyan | AK39: Giselle Sandoval | AL39: 9 31999094 | AM39: 9 74895268 | AO39: 172 | AP39: 21 | AQ39: X | AR39: ACTIVA | AS39: INACTIVA | AT39: X
A40: 3 | B40: 41003048 | C40: 4187 | D40: MAULE | E40: =VLOOKUP(B40,'Maestros de Tiendas'!J:J,1,0) -> #REF! | F40: MARIA ANGELICA MEDINA | G40: ZONA SUR | H40: MAULE | I40: TALCA | J40: PLAZA MAULE | K40: APERTURADA | L40: 2 | M40: QUINCENAL | N40: ATHENA | O40: X | P40: X | Q40: X | R40: X | S40: X | T40: X | U40: X | V40: X | W40: X | X40: X | Y40: X | Z40: X | AA40: X | AB40: X | AC40: X | AD40: X | AF40: X | AG40: AV. CIRCUNVALACIÓN OTE. 1055, LOCAL 1111-1112, TALCA, MAULE | AH40: LUNES A DOMINGO DE 08:30 A 19:30 | AI40: Mallplazamaule@natura.net | AJ40: Claudia Aguirre | AK40: Viviana Ibañez O | AL40: ‎9 31999087 | AM40: 9 74895268 | AO40: 173 | AP40: 22 | AQ40: X | AR40: ACTIVA | AS40: INACTIVA | AT40: X
...

Sheet CARGA OC
A1: INGRESO | B1: USUARIO | C1: NOMBRE TIENDA | D1: COD SAP Proveedor | E1: NUMERO FACTURA | F1: FECHA EMISION | G1: DETALLE | H1: EXENTO | I1: NETO

Sheet CONSOLIDADO OC
A1: INGRESO | B1: USUARIO | C1: COD SAP Proveedor | D1: RUT | E1: NOMBRE | F1: NUMERO FACTURA | G1: FECHA EMISION | H1: DETALLE | I1: EXENTO | J1: NETO | K1: FECHA VENCIMIENTO | L1: IVA | M1: TOTAL | N1: MES | O1: OC | P1: Aprobador | Q1: Commodity | R1: Cuenta Contable | S1: Plan de Pago | T1: CECO | U1: Almacen SAP tienda | V1: NOMBRE TIENDA | W1: REALIZADA
A2: 46107.54 | B2: harrysyusti@natura.net | C2: 821848 | D2: 76231235-2 | E2: Bulevar Rentas Inmobiliarias S.A. | F2: 75246 | G2: 46056 | H2: ARRIENDO | J2: 4625725 | K2: 46066 | L2: 878888 | M2: 5504613 | N2: 3 | O2: 0 | P2: javiermancilla@natura.net | Q2: 50302002 | R2: 3305012006 | S2: CL15 | T2: 3305012006 | U2: 4160 | V2: Aeropuerto | W2: FALSE
A3: 46107.546 | B3: harrysyusti@natura.net | C3: 808291 | D3: 96847320-4 | E3: MALL DEL CENTRO DE CONCEPCION?S.P.A. | F3: 70517 | G3: 46056 | H3: Agua y Electricidad | J3: 4625725 | K3: 46066 | L3: 878888 | M3: 5504613 | N3: 3 | O3: 0 | P3: javiermancilla@natura.net | Q3: 50302002 | R3: 3305012006 | S3: CL15 | T3: 3305012006 | U3: 4172 | V3: MALL DEL CENTRO DE CONCEPCION?S.P.A. | W3: FALSE

Sheet CORRECCION TIENDA
A1: Almacen SAP tienda | B1: nombre 1
A2: 4160 | B2: Sociedad Concesionaria Nuevo Pudahuel S.A.
A3: 4160 | B3: AEROPUERTO
A4: 4160 | B4: Aeropuerto
A5: 4191 | B5: Arauco ChillÃ¡n SPA
A6: 4191 | B6: ARAUCO CHILLAN
A7: 4191 | B7: Arauco Chillán
A8: 4196 | B8: Bulevar Rentas Inmobiliarias S.A.
A9: 4196 | B9: ARAUCO CORONEL
A10: 4196 | B10: Arauco Coronel
A11: 4197 | B11: Todo Arauco SpA
A12: 4197 | B12: ARAUCO BUENAVENTURA
A13: 4197 | B13: Arauco Premium Outlet Buenaventura
... A151: 4154 | B151: Zona Austral Punta Arenas

Sheet DCC TIENDA
A1: Almacen SAP tienda | B1: Nombre correcto | C1: CECO | D1: Mall | E1: Sigla
A2: 4160 | B2: Aeropuerto | C2: 41001163 | D2: AEROPUERTO | E2: AE
A3: 4191 | B3: Arauco Chillán | C3: 41003115 | D3: ARAUCO CHILLAN | E3: ACH
A4: 4196 | B4: Arauco Coronel | C4: 41001189 | D4: ARAUCO CORONEL | E4: AC
A5: 4197 | B5: Arauco Premium Outlet Buenaventura | C5: 41001184 | D5: ARAUCO BUENAVENTURA | E5: APOB
A6: 4149 | B6: Arauco Quilicura | C6: 41003113 | D6: ARAUCO QUILICURA | E6: MAQ
A7: 4189 | B7: Arauco San Antonio | C7: 41001099 | D7: SAN ANTONIO | E7: ASA
A8: 4198 | B8: Cenco Angamos | C8: 41001190 | D8: CENCO ANGAMOS | E8: CA
A9: 9203 | B9: Cenco Belloto | C9: 41001191 | D9: PORTAL BELLOTO | E9: CB
A10: 4162 | B10: Costanera Center | C10: 41003042 | D10: COSTANERA CENTER | E10: CC
A11: 4150 | B11: EU Gran Avenida | C11: 41003116 | D11: EU GRAN AVENIDA | E11: EUGA
A12: 4159 | B12: EU Melipilla | C12: 41001181 | D12: EU MELIPILLA | E12: EUME
A13: 4158 | B13: EU Puente Alto | C13: 41001177 | D13: EU PUENTE ALTO | E13: EUPA
... A49: 4154 | B49: Zona Austral Punta Arenas | C49: 41003118 | D49: PUNTA ARENAS ZONA FRANCA | E49: ZA

Sheet DCC PROVEEDOR
A1: COD SAP Proveedor | B1: RUT Proveedor | C1: NOMBRE | D1: Plan de Pago
A2: 156747 | B2: 78408990-8 | C2: ADM_C.C._CENCOSUD_SPA. | D2: CL15
A3: 815184 | B3: 76939541-5 | C3: Arauco Centros Comerciales Regionales SPA | D3: CL15
A4: 815562 | B4: 76939551-2 | C4: Arauco Chillan SPA | D4: CL15
A5: 800839 | B5: 96734110-K | C5: Arauco Malls Chile S.A. | D5: CL15
A6: 821848 | B6: 76231235-2 | C6: Bulevar Rentas Inmobiliarias S.A. | D6: CL15
A7: 801707 | B7: 76433310-1 | C7: Cencosud_Shopping_S.A. | D7: CL15
A8: 143255 | B8: 76203299-6 | C8: Comercializadora_Costanera_Center_SPA | D8: CL15
A9: 154155 | B9: 96571890-7 | C9: Compania de Seguros ConFuturo S.A. | D9: CL15
A10: 813536 | B10: 76111950-8 | C10: Desarrollo Inmobiliarios San Antonio S.A | D10: CL15
A11: 816644 | B11: 76156628-8 | C11: INMOBILIARIA BZ S A | D11: CL15
A12: 808766 | B12: 76186219-7 | C12: INMOBILIARIA CENTROS COMERCIALES I SPA | D12: CL15
A13: 820941 | B13: 96824450-7 | C13: INMOBILIARIA MALL LAS AMERICAS S.A. | D13: CL15
... A29: 821697 | B29: 96671020-9 | C29: Todo Arauco SpA | D29: CL15

Sheet proveedor-tienda
A1: Almacen SAP tienda | B1: COD SAP Proveedor
A2: 4169 | B2: 156747
A3: 4198 | B3: 156747
A4: 4162 | B4: 156747
A5: 4175 | B5: 156747
A6: 9203 | B6: 156747
A7: 4188 | B7: 156747
A8: 4192 | B8: 156747
A9: 4186 | B9: 156747
A10: 4149 | B10: 815184
A11: 4191 | B11: 815562
A12: 4168 | B12: 800839
A13: 4196 | B13: 821848
... A51: 4197 | B51: 821697

Sheet PROVEEDOR SERVICIO
A1: COD SAP Proveedor | B1: DETALLE | C1: MALL | D1: LLAVE | E1: cuenta contable | F1: commodity
A2: 820859 | B2: ARRIENDO | C2: AEROPUERTO | D2: =A2&B2 -> 820859ARRIENDO | E2: 3305012006 | F2: 50302002
A3: 156747 | B3: GASTO COMUN | C3: ALTO LAS CONDES | D3: =A3&B3 -> 156747GASTO COMUN | E3: 3305012006 | F3: 50302002
A4: 821697 | B4: ARRIENDO | C4: ARAUCO BUENAVENTURA | D4: =A4&B4 -> 821697ARRIENDO | E4: 3305012006 | F4: 50302002
A5: 821697 | B5: ELECTRICIDAD | C5: ARAUCO BUENAVENTURA | D5: =A5&B5 -> 821697ELECTRICIDAD | E5: 3305012006 | F5: 50302002
A6: 815562 | B6: ARRIENDO | C6: ARAUCO CHILLAN | D6: =A6&B6 -> 815562ARRIENDO | E6: 3305012006 | F6: 50302002
A7: 815562 | B7: ELECTRICIDAD | C7: ARAUCO CHILLAN | D7: =A7&B7 -> 815562ELECTRICIDAD | E7: 3305012006 | F7: 50302002
A8: 821848 | B8: ARRIENDO | C8: ARAUCO CORONEL | D8: =A8&B8 -> 821848ARRIENDO | E8: 3305012006 | F8: 50302002
A9: 821848 | B9: ELECTRICIDAD | C9: ARAUCO CORONEL | D9: =A9&B9 -> 821848ELECTRICIDAD | E9: 3305012006 | F9: 50302002
A10: 800839 | B10: ARRIENDO | C10: ARAUCO MAIPU | D10: =A10&B10 -> 800839ARRIENDO | E10: 3305012006 | F10: 50302002
A11: 800839 | B11: ARRIENDO VARIABLE, ELECTRICIDAD | C11: ARAUCO MAIPU | D11: =A11&B11 -> 800839ARRIENDO VARIABLE, ELECTRICIDAD | E11: 3305012006 | F11: 50302002
A12: 815184 | B12: ARRIENDO | C12: ARAUCO QUILICURA | D12: =A12&B12 -> 815184ARRIENDO | E12: 3305012006 | F12: 50302002
A13: 815184 | B13: ELECTRICIDAD | C13: ARAUCO QUILICURA | D13: =A13&B13 -> 815184ELECTRICIDAD | E13: 3305012006 | F13: 50302002
... A90: 818541 | B90: MTTO | C90: VIVO COQUIMBO | D90: =A90&B90 -> 818541MTTO | E90: 3305012006 | F90: 50302002

Sheet Hoja 4
A1: N° | B1: Mall | C1: Sigla | D1: Supervisor | E1: CECO | F1: Status | G1: Almacen SAP | H1: Fecha apertura | I1: Fecha vencimiento contrato | J1: Fecha Re apertura | K1: Mall
A2: 32 | B2: MallPlaza Sur | C2: MPS | E2: 41001095 | F2: Abierta | G2: 4147 | H2: 45532 | I2: 47358 | K2: MallPlaza Sur
A3: 31 | B3: Mall Plaza Copiapo | C3: MPC | E3: 41001098 | F3: Abierta | G3: 4148 | H3: 45512 | I3: 47338 | K3: Mall Plaza Copiapo
A4: 34 | B4: Arauco Quilicura | C4: MAQ | E4: 41003113 | F4: Abierta | G4: 4149 | H4: 45551 | I4: 47012 | K4: Arauco Quilicura
A5: 33 | B5: EU Gran Avenida | C5: EUGA | E5: 41003116 | F5: Abierta | G5: 4150 | H5: 45545 | I5: 47006 | K5: EU Gran Avenida
A6: 36 | B6: Paseo Quilin | C6: MPQ | E6: 41001152 | F6: Abierta | G6: 4151 | H6: 45582 | I6: 47408 | K6: Paseo Quilin
A7: 35 | B7: Mall Paseo Chiloé | C7: MCH | E7: 41003117 | F7: Abierta | G7: 4152 | H7: 45589 | I7: 47050 | K7: Mall Paseo Chiloé
A8: 38 | B8: Mall Paseo Costanera Pto Montt | C8: MPM | E8: 41001156 | F8: Abierta | G8: 4153 | H8: 45615 | I8: 47076 | K8: Mall Paseo Costanera Pto Montt
A9: 37 | B9: Zona Austral Punta Arenas | C9: ZA | E9: 41003118 | F9: Abierta | G9: 4154 | H9: 45610 | I9: 47071 | K9: Zona Austral Punta Arenas
A10: 39 | B10: Paseo Ross | C10: PS | E10: 41001161 | F10: Abierta | G10: 4155 | H10: 45623 | I10: 47084 | K10: Paseo Ross
A11: 40 | B11: Vivo Coquimbo | C11: VCOQ | E11: 41001164 | F11: Abierta | G11: 4156 | H11: 45638 | I11: 47099 | K11: Vivo Coquimbo
A12: 45 | B12: Open Ovalle | C12: OO | E12: 41001176 | F12: Abierta | G12: 4157 | H12: 45806 | K12: Open Ovalle
A13: 44 | B13: EU Puente Alto | C13: EUPA | E13: 41001177 | F13: Abierta | G13: 4158 | H13: 45797 | K13: EU Puente Alto
A14: 47 | B14: EU Melipilla | C14: EUME | E14: 41001181 | F14: Abierta | G14: 4159 | H14: 45841 | K14: EU Melipilla
A15: 41 | B15: Aeropuerto | C15: AE | E15: 41001163 | F15: Abierta | G15: 4160 | H15: 46007 | K15: Aeropuerto
A16: 1 | B16: Mallplaza Los Dominicos | C16: PLD | D16: Seba/DRP | E16: 41003043 | F16: Abierta | G16: 4161 | H16: 43070 | I16: 45992 | K16: Mallplaza Los Dominicos
A17: 2 | B17: Costanera Center | C17: CC | D17: Luis/DRP | E17: 41003042 | F17: Abierta | G17: 4162 | H17: 43453 | I17: 47391 | J17: 45626 | K17: Costanera Center
A18: 3 | B18: Mallplaza Egaña | C18: PEG | D18: Luis/DRP | E18: 41003008 | F18: Abierta | G18: 4163 | H18: 44181 | I18: 45858 | K18: Mallplaza Egaña
A19: 4 | B19: Mallplaza Norte | C19: PNO | D19: Angie/Urrutia | E19: 41003009 | F19: Abierta | G19: 4164 | H19: 44405 | I19: 46126 | K19: Mallplaza Norte
A20: 7 | B20: Mallplaza Vespucio | C20: PVE | D20: Seba/Urrutia | E20: 41003010 | F20: Abierta | G20: 4165 | H20: 44593 | I20: 46369 | K20: Mallplaza Vespucio
A21: 5 | B21: Parque Arauco | C21: PAK | D21: Luis/DRP | E21: 41003011 | F21: Abierta | G21: 4166 | H21: 44518 | I21: 45838 | K21: Parque Arauco
A22: 6 | B22: Mall Arauco Maipú | C22: MAM | D22: Seba/Urrutia | E22: 41003016 | F22: Abierta | G22: 4168 | H22: 44531 | I22: 45822 | K22: Mall Arauco Maipú
A23: 8 | B23: Mall Alto Las Condes | C23: ALC | D23: Luis/DRP | E23: 41003017 | F23: Abierta | G23: 4169 | H23: 44655 | I23: 46356 | K23: Mall Alto Las Condes
A24: 9 | B24: Mall Marina | C24: MM | D24: Luis/DRP | E24: 41003019 | F24: Abierta | G24: 4170 | H24: 44715 | I24: 46754 | K24: Mall Marina
A25: 10 | B25: Mall Plaza Oeste | C25: POE | D25: Seba/Urrutia | E25: 41003021 | F25: Abierta | G25: 4171 | H25: 44784 | I25: 46610 | K25: Mall Plaza Oeste
A26: 14 | B26: Mall Del Centro Concepción | C26: MCC | D26: Seba/Urrutia | E26: 41003024 | F26: Abierta | G26: 4172 | H26: 44931 | I26: 46392 | K26: Mall Del Centro Concepción
A27: 12 | B27: Mallplaza Trebol | C27: MPT | D27: Seba/Urrutia | E27: 41003022 | F27: Abierta | G27: 4173 | H27: 44890 | I27: 46716 | K27: Mallplaza Trebol
A28: 11 | B28: Mall Florida Center | C28: FC | D28: Seba/Urrutia | E28: 41003020 | F28: Abierta | G28: 4175 | H28: 44846 | I28: 46307 | K28: Mall Florida Center
A29: 15 | B29: Mercado Urbano Tobalaba | C29: MUT | D29: Luis/DRP | E29: 41003013 | F29: Abierta | G29: 4176 | H29: 45138 | I29: 46599 | K29: Mercado Urbano Tobalaba
A30: 13 | B30: Mall Barrio Independencia | C30: MBI | D30: Seba/Urrutia | E30: 41003023 | F30: Abierta | G30: 4177 | H30: 44915 | I30: 46376 | K30: Mall Barrio Independencia
A31: 26 | B31: MallPlaza Tobalaba | C31: MPT | E31: 41001096 | F31: Abierta | G31: 4178 | H31: 45412 | I31: =H31+(365*5) -> 47237 | K31: MallPlaza Tobalaba
A32: 29 | B32: Mall Plaza Arica | C32: MPA | E32: 41001097 | F32: Abierta | G32: 4179 | H32: 45482 | I32: 47308 | K32: Mall Plaza Arica
A33: 17 | B33: MallPlaza Antofagasta | C33: PAN | D33: Luis/DRP | E33: 41003027 | F33: Abierta | G33: 4180 | H33: 45217 | I33: 47044 | K33: MallPlaza Antofagasta
A34: 18 | B34: MallPlaza Calama | C34: PCA | D34: Luis/DRP | E34: 41003026 | F34: Abierta | G34: 4181 | H34: 45148 | I34: 46975 | K34: MallPlaza Calama
A35: 16 | B35: Vivo El Centro (Puente) | C35: VCC | D35: Seba/Urrutia | E35: 41003028 | F35: Abierta | G35: 4182 | H35: 45121 | I35: 46582 | K35: Vivo El Centro (Puente)
A36: 19 | B36: MallPlaza Alameda | C36: PAL | D36: Seba/Urrutia | E36: 41003029 | F36: Abierta | G36: 4183 | H36: 45145 | I36: 46972 | K36: MallPlaza Alameda
A37: 23 | B37: Subcentro | C37: SC | D37: Luis/DRP | E37: 41001093 | F37: Abierta | G37: 4184 | H37: 45169 | I37: 46630 | K37: Subcentro
A38: 20 | B38: Mall Paseo Valdivia | C38: MPV | D38: Seba/Urrutia | E38: 41001101 | F38: Abierta | G38: 4185 | H38: 45183 | I38: 46644 | K38: Mall Paseo Valdivia
A39: 21 | B39: Portal Osorno | C39: PO | D39: Seba/Urrutia | E39: 41003030 | F39: Abierta | G39: 4186 | H39: 45209 | I39: 46670 | K39: Portal Osorno
A40: 22 | B40: Plaza Maule | C40: PM | D40: Seba/Urrutia | E40: 41003048 | F40: Abierta | G40: 4187 | H40: 45253 | I40: 46714 | K40: Plaza Maule
...

Sheet Hoja 15
A1: INGRESO | B1: USUARIO | C1: NOMBRE TIENDA | D1: COD SAP Proveedor | E1: NUMERO FACTURA | F1: FECHA EMISION | G1: DETALLE | H1: EXENTO | I1: NETO
A2: 46105.604 | B2: harrysyusti@natura.net | C2: MALL DEL CENTRO DE CONCEPCION?S.P.A. | D2: 808291 | E2: 70517 | F2: 46056 | G2: TEST | I2: 4625725
D3: 801707 | E3: 165651 | F3: 46084 | G3: ARRIENDO | H3: 479505 | I3: 5126607
D4: 156747 | E4: 789951 | F4: 46084 | G4: PUBLICIDAD | H4: - | I4: 318461
D5: 813426 | E5: 48695 | F5: 46056 | G5: Agua y Electricidad | H5: - | I5: 182014
D6: 816644 | E6: 25441 | F6: 46084 | G6: ELECTRICIDAD | H6: - | I6: 161768
D7: 808766 | E7: 38701 | F7: 46084 | G7: ARRIENDO | H7: - | I7: 2745254
D8: 808766 | E8: 38702 | F8: 46084 | G8: BODEGA ARRIENDO | H8: - | I8: 288295
D9: 154155 | E9: 273744 | F9: 46085 | G9: ARRIENDO | H9: 210489 | I9: 2284570
D10: 154155 | E10: 274327 | F10: 46085 | G10: ARRIENDO | H10: 322229 | I10: 2879618
D11: 154155 | E11: 274472 | F11: 46085 | G11: ARRIENDO | H11: 546682 | I11: 3392214
D12: 801100 | E12: 190648 | F12: 46085 | G12: ARRIENDO | H12: 746666 | I12: 10708357
D13: 821697 | E13: 70617 | F13: 46085 | G13: ARRIENDO | H13: 255509 | I13: 3447541
D14: 800839 | E14: 100832 | F14: 46085 | G14: ARRIENDO | H14: 459189 | I14: 3580324
D15: 813536 | E15: 38943 | F15: 46085 | G15: ARRIENDO | H15: 495843 | I15: 2291090
D16: 821848 | E16: 31865 | F16: 46085 | G16: ARRIENDO | H16: - | I16: 2954149
D17: 815184 | E17: 24247 | F17: 46085 | G17: ARRIENDO | H17: 372994 | I17: 3277092
D18: 815562 | E18: 30031 | F18: 46085 | G18: ARRIENDO | H18: 589393 | I18: 6935326
D19: 801936 | E19: 251401 | F19: 46085 | G19: GGCC ADM | H19: - | I19: 1110780
D20: 808291 | E20: 75435 | F20: 46085 | G20: GGCC ADM | H20: - | I20: 1760713
D21: 808291 | E21: 75582 | F21: 46085 | G21: Agua y Electricidad | H21: 2733 | I21: 426768
D22: 801936 | E22: 251619 | F22: 46085 | G22: GGCC ADM | H22: - | I22: 1777171
D23: 801936 | E23: 251781 | F23: 46085 | G23: Agua y Electricidad | H23: 6765 | I23: 635640
D24: 801936 | E24: 252061 | F24: 46085 | G24: Agua y Electricidad | H24: 2706 | I24: 193964
D25: 156747 | E25: 790070 | F25: 46085 | G25: GASTO COMUN | H25: - | I25: 1640819
D26: 156747 | E26: 790169 | F26: 46085 | G26: GASTO COMUN | H26: - | I26: 1164686
D27: 156747 | E27: 790464 | F27: 46085 | G27: GASTO COMUN | H27: - | I27: 2586845
D28: 156747 | E28: 790465 | F28: 46085 | G28: GASTO COMUN | H28: - | I28: 1986421
D29: 156747 | E29: 794662 | F29: 46085 | G29: GASTO COMUN | H29: - | I29: 1711263
D30: 156747 | E30: 795056 | F30: 46085 | G30: GASTO COMUN | H30: - | I30: 1440750
D31: 156747 | E31: 795350 | F31: 46085 | G31: GASTO COMUN | H31: - | I31: 3467050
D32: 156747 | E32: 794957 | F32: 46085 | G32: GASTO COMUN | H32: - | I32: 2347078
D33: 817165 | E33: 143090 | F33: 46080 | G33: MULTAS E INTERES | H33: 48951 | I33: -
D34: 820859 | E34: 49614 | F34: 46084 | G34: ARRIENDO | H34: 3702430 | I34: -
D35: 817165 | E35: 37142 | F35: 46081 | G35: GASTO COMUN | H35: 903499 | I35: -
D36: 809145 | E36: 231068 | F36: 46087 | G36: ARRIENDO VARIABLE | H36: - | I36: 708584
D37: 809145 | E37: 231155 | F37: 46087 | G37: ARRIENDO VARIABLE | H37: - | I37: 457983
D38: 803668 | E38: 13842 | F38: 46087 | G38: ARRIENDO BODEGA | H38: - | I38: 1188318
D39: 803668 | E39: 13890 | F39: 46087 | G39: ARRIENDO | H39: 1172205 | I39: 4148760
D40: 816449 | E40: 40546 | F40: 46090 | G40: ARRIENDO | H40: - | I40: 3559277
...
